Workbook

Sheet Line Follower
B2: Error Constants | I2: =I6*(COLUMN(A1)-1)*$C$3 -> 0 | J2: =J6*(COLUMN(B1)-1)*$C$3 -> 0 | K2: =K6*(COLUMN(C1)-1)*$C$3 -> 0 | L2: =L6*(COLUMN(D1)-1)*$C$3 -> 6 | M2: Errors | N2: =N6*(COLUMN(E1)-1)*$C$3 -> 8 | O2: =O6*(COLUMN(F1)-1)*$C$3 -> 0 | P2: =P6*(COLUMN(G1)-1)*$C$3 -> 0 | Q2: =Q6*(COLUMN(H1)-1)*$C$3 -> 0
B3: Error weight | C3: 2
B4: Total central sensors | C4: 8
B5: Avg error | C5: =C3*(C4-1)/2 -> 7
B6: Max error | C6: =(C4-1)*C3-C5 -> 7 | G6: 1 | I6: 0 | J6: 0 | K6: 0 | L6: 1 | M6: 1 | N6: 1 | O6: 0 | P6: 0 | Q6: 0 | S6: 0
B7: Min error | C7: =-C6 -> -7 | G7: IR1 | I7: IR2 | J7: IR3 | K7: IR4 | L7: IR5 | M7: IR6 | N7: IR8 | O7: IR9 | P7: IR10 | Q7: IR11 | S7: IR12
B9: Error Values
B10: Total Error | C10: =SUM(I2:L2,N2:Q2) -> 14
B11: Central Sensors | C11: =SUM(I6:L6,N6:Q6) -> 2
B12: Error | C12: =IF(AND(C11=0,M6=1),0,INT(C10/C11-C5)) -> 0
B13: Last Error | C13: -7
B15: Observer
B16: line | C16: {=TRANSPOSE(_xlfn.XLOOKUP(_xlfn.TEXTJOIN(,,G6,I6:Q6,S6,M17),Aux!B3:B4098,'Truth Table'!O3:S4098))=1} -> TRUE
B17: straight | C17: TRUE | M17: 1
B18: crossing | C18: FALSE | M18: IR7
B19: curve | C19: TRUE
B20: marker | C20: FALSE
B21: lost left | C21: =AND(_xlfn.XLOOKUP(_xlfn.TEXTJOIN(,,G6,I6:Q6,S6,M17),Aux!B3:B4098,'Truth Table'!T3:T4098)=1,C13<=C7) -> FALSE
B22: lost right | C22: =AND(_xlfn.XLOOKUP(_xlfn.TEXTJOIN(,,G6,I6:Q6,S6,M17),Aux!B3:B4098,'Truth Table'!U3:U4098)=1,C13>=C6) -> FALSE
B23: pitch | C23: =AND(_xlfn.XLOOKUP(_xlfn.TEXTJOIN(,,G6,I6:Q6,S6,M17),Aux!B3:B4098,'Truth Table'!V3:V4098)=1,ABS(C13)<C6) -> FALSE

Sheet Truth Table
B2: Left | C2: IR2 | D2: IR3 | E2: IR4 | F2: IR5 | G2: Center | H2: IR8 | I2: IR9 | J2: IR10 | K2: IR11 | L2: Right | M2: Middle | N2: Error | O2: line | P2: straight | Q2: crossing | R2: curve | S2: marker | T2: left | U2: right | V2: pitch
B3: 0 | C3: 0 | D3: 0 | E3: 0 | F3: 0 | G3: 0 | H3: 0 | I3: 0 | J3: 0 | K3: 0 | L3: 0 | M3: 0 | N3: {=IF(OR(ISNUMBER(FIND(Aux!$D$3:$D$9,_xlfn.TEXTJOIN(,,C3:K3)))),NA(),IF(AND(SUM(C3:F3,H3:K3)=0,G3=1),0,INT((SUMPRODUCT(C3:F3,COLUMN($A$1:$D$1)-1)+SUMPRODUCT(H3:K3,COLUMN($E$1:$H$1)-1))*'Line Follower'!$C$3/SUM(C3:F3,H3:K3)-'Line Follower'!$C$5)))} -> #DIV/0! | O3: {=IF(ABS(N3:N4098)<='Line Follower'!$C$6,1,0)} -> #DIV/0! | P3: =IF(AND(N3=0,G3=1,M3=1),1,0) -> #DIV/0! | Q3: =IF(ISERROR(N3),N3,IF(SUM(C3:K3)>=4,1,0)) -> #DIV/0! | R3: =IF(AND(B3=1,N3>'Line Follower'!$C$7,SUM(C3:K3)<4),1,0) -> #DIV/0! | S3: =IF(AND(L3=1,N3<'Line Follower'!$C$6,SUM(C3:K3)<4),1,0) -> #DIV/0! | T3: =IF(ISNA(N3),NA(),IF(SUM(C3:L3)=0,1,0)) -> 1 | U3: =IF(ISNA(N3),NA(),IF(SUM(B3:K3)=0,1,0)) -> 1 | V3: =IF(ISNA(N3),NA(),IF(SUM(B3:L3)=0,1,0)) -> 1
B4: 1 | C4: 0 | D4: 0 | E4: 0 | F4: 0 | G4: 0 | H4: 0 | I4: 0 | J4: 0 | K4: 0 | L4: 0 | M4: 0 | N4: {=IF(OR(ISNUMBER(FIND(Aux!$D$3:$D$9,_xlfn.TEXTJOIN(,,C4:K4)))),NA(),IF(AND(SUM(C4:F4,H4:K4)=0,G4=1),0,INT((SUMPRODUCT(C4:F4,COLUMN($A$1:$D$1)-1)+SUMPRODUCT(H4:K4,COLUMN($E$1:$H$1)-1))*'Line Follower'!$C$3/SUM(C4:F4,H4:K4)-'Line Follower'!$C$5)))} -> #DIV/0! | O4: #DIV/0! | P4: =IF(AND(N4=0,G4=1,M4=1),1,0) -> #DIV/0! | Q4: =IF(ISERROR(N4),N4,IF(SUM(C4:K4)>=4,1,0)) -> #DIV/0! | R4: =IF(AND(B4=1,N4>'Line Follower'!$C$7,SUM(C4:K4)<4),1,0) -> #DIV/0! | S4: =IF(AND(L4=1,N4<'Line Follower'!$C$6,SUM(C4:K4)<4),1,0) -> #DIV/0! | T4: =IF(ISNA(N4),NA(),IF(SUM(C4:L4)=0,1,0)) -> 1 | U4: =IF(ISNA(N4),NA(),IF(SUM(B4:K4)=0,1,0)) -> 0 | V4: =IF(ISNA(N4),NA(),IF(SUM(B4:L4)=0,1,0)) -> 0
B5: 0 | C5: 1 | D5: 0 | E5: 0 | F5: 0 | G5: 0 | H5: 0 | I5: 0 | J5: 0 | K5: 0 | L5: 0 | M5: 0 | N5: {=IF(OR(ISNUMBER(FIND(Aux!$D$3:$D$9,_xlfn.TEXTJOIN(,,C5:K5)))),NA(),IF(AND(SUM(C5:F5,H5:K5)=0,G5=1),0,INT((SUMPRODUCT(C5:F5,COLUMN($A$1:$D$1)-1)+SUMPRODUCT(H5:K5,COLUMN($E$1:$H$1)-1))*'Line Follower'!$C$3/SUM(C5:F5,H5:K5)-'Line Follower'!$C$5)))} -> -7 | O5: 1 | P5: =IF(AND(N5=0,G5=1,M5=1),1,0) -> 0 | Q5: =IF(ISERROR(N5),N5,IF(SUM(C5:K5)>=4,1,0)) -> 0 | R5: =IF(AND(B5=1,N5>'Line Follower'!$C$7,SUM(C5:K5)<4),1,0) -> 0 | S5: =IF(AND(L5=1,N5<'Line Follower'!$C$6,SUM(C5:K5)<4),1,0) -> 0 | T5: =IF(ISNA(N5),NA(),IF(SUM(C5:L5)=0,1,0)) -> 0 | U5: =IF(ISNA(N5),NA(),IF(SUM(B5:K5)=0,1,0)) -> 0 | V5: =IF(ISNA(N5),NA(),IF(SUM(B5:L5)=0,1,0)) -> 0
B6: 1 | C6: 1 | D6: 0 | E6: 0 | F6: 0 | G6: 0 | H6: 0 | I6: 0 | J6: 0 | K6: 0 | L6: 0 | M6: 0 | N6: {=IF(OR(ISNUMBER(FIND(Aux!$D$3:$D$9,_xlfn.TEXTJOIN(,,C6:K6)))),NA(),IF(AND(SUM(C6:F6,H6:K6)=0,G6=1),0,INT((SUMPRODUCT(C6:F6,COLUMN($A$1:$D$1)-1)+SUMPRODUCT(H6:K6,COLUMN($E$1:$H$1)-1))*'Line Follower'!$C$3/SUM(C6:F6,H6:K6)-'Line Follower'!$C$5)))} -> -7 | O6: 1 | P6: =IF(AND(N6=0,G6=1,M6=1),1,0) -> 0 | Q6: =IF(ISERROR(N6),N6,IF(SUM(C6:K6)>=4,1,0)) -> 0 | R6: =IF(AND(B6=1,N6>'Line Follower'!$C$7,SUM(C6:K6)<4),1,0) -> 0 | S6: =IF(AND(L6=1,N6<'Line Follower'!$C$6,SUM(C6:K6)<4),1,0) -> 0 | T6: =IF(ISNA(N6),NA(),IF(SUM(C6:L6)=0,1,0)) -> 0 | U6: =IF(ISNA(N6),NA(),IF(SUM(B6:K6)=0,1,0)) -> 0 | V6: =IF(ISNA(N6),NA(),IF(SUM(B6:L6)=0,1,0)) -> 0
B7: 0 | C7: 0 | D7: 1 | E7: 0 | F7: 0 | G7: 0 | H7: 0 | I7: 0 | J7: 0 | K7: 0 | L7: 0 | M7: 0 | N7: {=IF(OR(ISNUMBER(FIND(Aux!$D$3:$D$9,_xlfn.TEXTJOIN(,,C7:K7)))),NA(),IF(AND(SUM(C7:F7,H7:K7)=0,G7=1),0,INT((SUMPRODUCT(C7:F7,COLUMN($A$1:$D$1)-1)+SUMPRODUCT(H7:K7,COLUMN($E$1:$H$1)-1))*'Line Follower'!$C$3/SUM(C7:F7,H7:K7)-'Line Follower'!$C$5)))} -> -5 | O7: 1 | P7: =IF(AND(N7=0,G7=1,M7=1),1,0) -> 0 | Q7: =IF(ISERROR(N7),N7,IF(SUM(C7:K7)>=4,1,0)) -> 0 | R7: =IF(AND(B7=1,N7>'Line Follower'!$C$7,SUM(C7:K7)<4),1,0) -> 0 | S7: =IF(AND(L7=1,N7<'Line Follower'!$C$6,SUM(C7:K7)<4),1,0) -> 0 | T7: =IF(ISNA(N7),NA(),IF(SUM(C7:L7)=0,1,0)) -> 0 | U7: =IF(ISNA(N7),NA(),IF(SUM(B7:K7)=0,1,0)) -> 0 | V7: =IF(ISNA(N7),NA(),IF(SUM(B7:L7)=0,1,0)) -> 0
B8: 1 | C8: 0 | D8: 1 | E8: 0 | F8: 0 | G8: 0 | H8: 0 | I8: 0 | J8: 0 | K8: 0 | L8: 0 | M8: 0 | N8: {=IF(OR(ISNUMBER(FIND(Aux!$D$3:$D$9,_xlfn.TEXTJOIN(,,C8:K8)))),NA(),IF(AND(SUM(C8:F8,H8:K8)=0,G8=1),0,INT((SUMPRODUCT(C8:F8,COLUMN($A$1:$D$1)-1)+SUMPRODUCT(H8:K8,COLUMN($E$1:$H$1)-1))*'Line Follower'!$C$3/SUM(C8:F8,H8:K8)-'Line Follower'!$C$5)))} -> -5 | O8: 1 | P8: =IF(AND(N8=0,G8=1,M8=1),1,0) -> 0 | Q8: =IF(ISERROR(N8),N8,IF(SUM(C8:K8)>=4,1,0)) -> 0 | R8: =IF(AND(B8=1,N8>'Line Follower'!$C$7,SUM(C8:K8)<4),1,0) -> 1 | S8: =IF(AND(L8=1,N8<'Line Follower'!$C$6,SUM(C8:K8)<4),1,0) -> 0 | T8: =IF(ISNA(N8),NA(),IF(SUM(C8:L8)=0,1,0)) -> 0 | U8: =IF(ISNA(N8),NA(),IF(SUM(B8:K8)=0,1,0)) -> 0 | V8: =IF(ISNA(N8),NA(),IF(SUM(B8:L8)=0,1,0)) -> 0
B9: 0 | C9: 1 | D9: 1 | E9: 0 | F9: 0 | G9: 0 | H9: 0 | I9: 0 | J9: 0 | K9: 0 | L9: 0 | M9: 0 | N9: {=IF(OR(ISNUMBER(FIND(Aux!$D$3:$D$9,_xlfn.TEXTJOIN(,,C9:K9)))),NA(),IF(AND(SUM(C9:F9,H9:K9)=0,G9=1),0,INT((SUMPRODUCT(C9:F9,COLUMN($A$1:$D$1)-1)+SUMPRODUCT(H9:K9,COLUMN($E$1:$H$1)-1))*'Line Follower'!$C$3/SUM(C9:F9,H9:K9)-'Line Follower'!$C$5)))} -> -6 | O9: 1 | P9: =IF(AND(N9=0,G9=1,M9=1),1,0) -> 0 | Q9: =IF(ISERROR(N9),N9,IF(SUM(C9:K9)>=4,1,0)) -> 0 | R9: =IF(AND(B9=1,N9>'Line Follower'!$C$7,SUM(C9:K9)<4),1,0) -> 0 | S9: =IF(AND(L9=1,N9<'Line Follower'!$C$6,SUM(C9:K9)<4),1,0) -> 0 | T9: =IF(ISNA(N9),NA(),IF(SUM(C9:L9)=0,1,0)) -> 0 | U9: =IF(ISNA(N9),NA(),IF(SUM(B9:K9)=0,1,0)) -> 0 | V9: =IF(ISNA(N9),NA(),IF(SUM(B9:L9)=0,1,0)) -> 0
B10: 1 | C10: 1 | D10: 1 | E10: 0 | F10: 0 | G10: 0 | H10: 0 | I10: 0 | J10: 0 | K10: 0 | L10: 0 | M10: 0 | N10: {=IF(OR(ISNUMBER(FIND(Aux!$D$3:$D$9,_xlfn.TEXTJOIN(,,C10:K10)))),NA(),IF(AND(SUM(C10:F10,H10:K10)=0,G10=1),0,INT((SUMPRODUCT(C10:F10,COLUMN($A$1:$D$1)-1)+SUMPRODUCT(H10:K10,COLUMN($E$1:$H$1)-1))*'Line Follower'!$C$3/SUM(C10:F10,H10:K10)-'Line Follower'!$C$5)))} -> -6 | O10: 1 | P10: =IF(AND(N10=0,G10=1,M10=1),1,0) -> 0 | Q10: =IF(ISERROR(N10),N10,IF(SUM(C10:K10)>=4,1,0)) -> 0 | R10: =IF(AND(B10=1,N10>'Line Follower'!$C$7,SUM(C10:K10)<4),1,0) -> 1 | S10: =IF(AND(L10=1,N10<'Line Follower'!$C$6,SUM(C10:K10)<4),1,0) -> 0 | T10: =IF(ISNA(N10),NA(),IF(SUM(C10:L10)=0,1,0)) -> 0 | U10: =IF(ISNA(N10),NA(),IF(SUM(B10:K10)=0,1,0)) -> 0 | V10: =IF(ISNA(N10),NA(),IF(SUM(B10:L10)=0,1,0)) -> 0
B11: 0 | C11: 0 | D11: 0 | E11: 1 | F11: 0 | G11: 0 | H11: 0 | I11: 0 | J11: 0 | K11: 0 | L11: 0 | M11: 0 | N11: {=IF(OR(ISNUMBER(FIND(Aux!$D$3:$D$9,_xlfn.TEXTJOIN(,,C11:K11)))),NA(),IF(AND(SUM(C11:F11,H11:K11)=0,G11=1),0,INT((SUMPRODUCT(C11:F11,COLUMN($A$1:$D$1)-1)+SUMPRODUCT(H11:K11,COLUMN($E$1:$H$1)-1))*'Line Follower'!$C$3/SUM(C11:F11,H11:K11)-'Line Follower'!$C$5)))} -> -3 | O11: 1 | P11: =IF(AND(N11=0,G11=1,M11=1),1,0) -> 0 | Q11: =IF(ISERROR(N11),N11,IF(SUM(C11:K11)>=4,1,0)) -> 0 | R11: =IF(AND(B11=1,N11>'Line Follower'!$C$7,SUM(C11:K11)<4),1,0) -> 0 | S11: =IF(AND(L11=1,N11<'Line Follower'!$C$6,SUM(C11:K11)<4),1,0) -> 0 | T11: =IF(ISNA(N11),NA(),IF(SUM(C11:L11)=0,1,0)) -> 0 | U11: =IF(ISNA(N11),NA(),IF(SUM(B11:K11)=0,1,0)) -> 0 | V11: =IF(ISNA(N11),NA(),IF(SUM(B11:L11)=0,1,0)) -> 0
B12: 1 | C12: 0 | D12: 0 | E12: 1 | F12: 0 | G12: 0 | H12: 0 | I12: 0 | J12: 0 | K12: 0 | L12: 0 | M12: 0 | N12: {=IF(OR(ISNUMBER(FIND(Aux!$D$3:$D$9,_xlfn.TEXTJOIN(,,C12:K12)))),NA(),IF(AND(SUM(C12:F12,H12:K12)=0,G12=1),0,INT((SUMPRODUCT(C12:F12,COLUMN($A$1:$D$1)-1)+SUMPRODUCT(H12:K12,COLUMN($E$1:$H$1)-1))*'Line Follower'!$C$3/SUM(C12:F12,H12:K12)-'Line Follower'!$C$5)))} -> -3 | O12: 1 | P12: =IF(AND(N12=0,G12=1,M12=1),1,0) -> 0 | Q12: =IF(ISERROR(N12),N12,IF(SUM(C12:K12)>=4,1,0)) -> 0 | R12: =IF(AND(B12=1,N12>'Line Follower'!$C$7,SUM(C12:K12)<4),1,0) -> 1 | S12: =IF(AND(L12=1,N12<'Line Follower'!$C$6,SUM(C12:K12)<4),1,0) -> 0 | T12: =IF(ISNA(N12),NA(),IF(SUM(C12:L12)=0,1,0)) -> 0 | U12: =IF(ISNA(N12),NA(),IF(SUM(B12:K12)=0,1,0)) -> 0 | V12: =IF(ISNA(N12),NA(),IF(SUM(B12:L12)=0,1,0)) -> 0
B13: 0 | C13: 1 | D13: 0 | E13: 1 | F13: 0 | G13: 0 | H13: 0 | I13: 0 | J13: 0 | K13: 0 | L13: 0 | M13: 0 | N13: {=IF(OR(ISNUMBER(FIND(Aux!$D$3:$D$9,_xlfn.TEXTJOIN(,,C13:K13)))),NA(),IF(AND(SUM(C13:F13,H13:K13)=0,G13=1),0,INT((SUMPRODUCT(C13:F13,COLUMN($A$1:$D$1)-1)+SUMPRODUCT(H13:K13,COLUMN($E$1:$H$1)-1))*'Line Follower'!$C$3/SUM(C13:F13,H13:K13)-'Line Follower'!$C$5)))} -> #N/A | O13: #N/A | P13: =IF(AND(N13=0,G13=1,M13=1),1,0) -> #N/A | Q13: =IF(ISERROR(N13),N13,IF(SUM(C13:K13)>=4,1,0)) -> #N/A | R13: =IF(AND(B13=1,N13>'Line Follower'!$C$7,SUM(C13:K13)<4),1,0) -> #N/A | S13: =IF(AND(L13=1,N13<'Line Follower'!$C$6,SUM(C13:K13)<4),1,0) -> #N/A | T13: =IF(ISNA(N13),NA(),IF(SUM(C13:L13)=0,1,0)) -> #N/A | U13: =IF(ISNA(N13),NA(),IF(SUM(B13:K13)=0,1,0)) -> #N/A | V13: =IF(ISNA(N13),NA(),IF(SUM(B13:L13)=0,1,0)) -> #N/A
B14: 1 | C14: 1 | D14: 0 | E14: 1 | F14: 0 | G14: 0 | H14: 0 | I14: 0 | J14: 0 | K14: 0 | L14: 0 | M14: 0 | N14: {=IF(OR(ISNUMBER(FIND(Aux!$D$3:$D$9,_xlfn.TEXTJOIN(,,C14:K14)))),NA(),IF(AND(SUM(C14:F14,H14:K14)=0,G14=1),0,INT((SUMPRODUCT(C14:F14,COLUMN($A$1:$D$1)-1)+SUMPRODUCT(H14:K14,COLUMN($E$1:$H$1)-1))*'Line Follower'!$C$3/SUM(C14:F14,H14:K14)-'Line Follower'!$C$5)))} -> #N/A | O14: #N/A | P14: =IF(AND(N14=0,G14=1,M14=1),1,0) -> #N/A | Q14: =IF(ISERROR(N14),N14,IF(SUM(C14:K14)>=4,1,0)) -> #N/A | R14: =IF(AND(B14=1,N14>'Line Follower'!$C$7,SUM(C14:K14)<4),1,0) -> #N/A | S14: =IF(AND(L14=1,N14<'Line Follower'!$C$6,SUM(C14:K14)<4),1,0) -> #N/A | T14: =IF(ISNA(N14),NA(),IF(SUM(C14:L14)=0,1,0)) -> #N/A | U14: =IF(ISNA(N14),NA(),IF(SUM(B14:K14)=0,1,0)) -> #N/A | V14: =IF(ISNA(N14),NA(),IF(SUM(B14:L14)=0,1,0)) -> #N/A
B15: 0 | C15: 0 | D15: 1 | E15: 1 | F15: 0 | G15: 0 | H15: 0 | I15: 0 | J15: 0 | K15: 0 | L15: 0 | M15: 0 | N15: {=IF(OR(ISNUMBER(FIND(Aux!$D$3:$D$9,_xlfn.TEXTJOIN(,,C15:K15)))),NA(),IF(AND(SUM(C15:F15,H15:K15)=0,G15=1),0,INT((SUMPRODUCT(C15:F15,COLUMN($A$1:$D$1)-1)+SUMPRODUCT(H15:K15,COLUMN($E$1:$H$1)-1))*'Line Follower'!$C$3/SUM(C15:F15,H15:K15)-'Line Follower'!$C$5)))} -> -4 | O15: 1 | P15: =IF(AND(N15=0,G15=1,M15=1),1,0) -> 0 | Q15: =IF(ISERROR(N15),N15,IF(SUM(C15:K15)>=4,1,0)) -> 0 | R15: =IF(AND(B15=1,N15>'Line Follower'!$C$7,SUM(C15:K15)<4),1,0) -> 0 | S15: =IF(AND(L15=1,N15<'Line Follower'!$C$6,SUM(C15:K15)<4),1,0) -> 0 | T15: =IF(ISNA(N15),NA(),IF(SUM(C15:L15)=0,1,0)) -> 0 | U15: =IF(ISNA(N15),NA(),IF(SUM(B15:K15)=0,1,0)) -> 0 | V15: =IF(ISNA(N15),NA(),IF(SUM(B15:L15)=0,1,0)) -> 0
B16: 1 | C16: 0 | D16: 1 | E16: 1 | F16: 0 | G16: 0 | H16: 0 | I16: 0 | J16: 0 | K16: 0 | L16: 0 | M16: 0 | N16: {=IF(OR(ISNUMBER(FIND(Aux!$D$3:$D$9,_xlfn.TEXTJOIN(,,C16:K16)))),NA(),IF(AND(SUM(C16:F16,H16:K16)=0,G16=1),0,INT((SUMPRODUCT(C16:F16,COLUMN($A$1:$D$1)-1)+SUMPRODUCT(H16:K16,COLUMN($E$1:$H$1)-1))*'Line Follower'!$C$3/SUM(C16:F16,H16:K16)-'Line Follower'!$C$5)))} -> -4 | O16: 1 | P16: =IF(AND(N16=0,G16=1,M16=1),1,0) -> 0 | Q16: =IF(ISERROR(N16),N16,IF(SUM(C16:K16)>=4,1,0)) -> 0 | R16: =IF(AND(B16=1,N16>'Line Follower'!$C$7,SUM(C16:K16)<4),1,0) -> 1 | S16: =IF(AND(L16=1,N16<'Line Follower'!$C$6,SUM(C16:K16)<4),1,0) -> 0 | T16: =IF(ISNA(N16),NA(),IF(SUM(C16:L16)=0,1,0)) -> 0 | U16: =IF(ISNA(N16),NA(),IF(SUM(B16:K16)=0,1,0)) -> 0 | V16: =IF(ISNA(N16),NA(),IF(SUM(B16:L16)=0,1,0)) -> 0
B17: 0 | C17: 1 | D17: 1 | E17: 1 | F17: 0 | G17: 0 | H17: 0 | I17: 0 | J17: 0 | K17: 0 | L17: 0 | M17: 0 | N17: {=IF(OR(ISNUMBER(FIND(Aux!$D$3:$D$9,_xlfn.TEXTJOIN(,,C17:K17)))),NA(),IF(AND(SUM(C17:F17,H17:K17)=0,G17=1),0,INT((SUMPRODUCT(C17:F17,COLUMN($A$1:$D$1)-1)+SUMPRODUCT(H17:K17,COLUMN($E$1:$H$1)-1))*'Line Follower'!$C$3/SUM(C17:F17,H17:K17)-'Line Follower'!$C$5)))} -> -5 | O17: 1 | P17: =IF(AND(N17=0,G17=1,M17=1),1,0) -> 0 | Q17: =IF(ISERROR(N17),N17,IF(SUM(C17:K17)>=4,1,0)) -> 0 | R17: =IF(AND(B17=1,N17>'Line Follower'!$C$7,SUM(C17:K17)<4),1,0) -> 0 | S17: =IF(AND(L17=1,N17<'Line Follower'!$C$6,SUM(C17:K17)<4),1,0) -> 0 | T17: =IF(ISNA(N17),NA(),IF(SUM(C17:L17)=0,1,0)) -> 0 | U17: =IF(ISNA(N17),NA(),IF(SUM(B17:K17)=0,1,0)) -> 0 | V17: =IF(ISNA(N17),NA(),IF(SUM(B17:L17)=0,1,0)) -> 0
B18: 1 | C18: 1 | D18: 1 | E18: 1 | F18: 0 | G18: 0 | H18: 0 | I18: 0 | J18: 0 | K18: 0 | L18: 0 | M18: 0 | N18: {=IF(OR(ISNUMBER(FIND(Aux!$D$3:$D$9,_xlfn.TEXTJOIN(,,C18:K18)))),NA(),IF(AND(SUM(C18:F18,H18:K18)=0,G18=1),0,INT((SUMPRODUCT(C18:F18,COLUMN($A$1:$D$1)-1)+SUMPRODUCT(H18:K18,COLUMN($E$1:$H$1)-1))*'Line Follower'!$C$3/SUM(C18:F18,H18:K18)-'Line Follower'!$C$5)))} -> -5 | O18: 1 | P18: =IF(AND(N18=0,G18=1,M18=1),1,0) -> 0 | Q18: =IF(ISERROR(N18),N18,IF(SUM(C18:K18)>=4,1,0)) -> 0 | R18: =IF(AND(B18=1,N18>'Line Follower'!$C$7,SUM(C18:K18)<4),1,0) -> 1 | S18: =IF(AND(L18=1,N18<'Line Follower'!$C$6,SUM(C18:K18)<4),1,0) -> 0 | T18: =IF(ISNA(N18),NA(),IF(SUM(C18:L18)=0,1,0)) -> 0 | U18: =IF(ISNA(N18),NA(),IF(SUM(B18:K18)=0,1,0)) -> 0 | V18: =IF(ISNA(N18),NA(),IF(SUM(B18:L18)=0,1,0)) -> 0
B19: 0 | C19: 0 | D19: 0 | E19: 0 | F19: 1 | G19: 0 | H19: 0 | I19: 0 | J19: 0 | K19: 0 | L19: 0 | M19: 0 | N19: {=IF(OR(ISNUMBER(FIND(Aux!$D$3:$D$9,_xlfn.TEXTJOIN(,,C19:K19)))),NA(),IF(AND(SUM(C19:F19,H19:K19)=0,G19=1),0,INT((SUMPRODUCT(C19:F19,COLUMN($A$1:$D$1)-1)+SUMPRODUCT(H19:K19,COLUMN($E$1:$H$1)-1))*'Line Follower'!$C$3/SUM(C19:F19,H19:K19)-'Line Follower'!$C$5)))} -> -1 | O19: 1 | P19: =IF(AND(N19=0,G19=1,M19=1),1,0) -> 0 | Q19: =IF(ISERROR(N19),N19,IF(SUM(C19:K19)>=4,1,0)) -> 0 | R19: =IF(AND(B19=1,N19>'Line Follower'!$C$7,SUM(C19:K19)<4),1,0) -> 0 | S19: =IF(AND(L19=1,N19<'Line Follower'!$C$6,SUM(C19:K19)<4),1,0) -> 0 | T19: =IF(ISNA(N19),NA(),IF(SUM(C19:L19)=0,1,0)) -> 0 | U19: =IF(ISNA(N19),NA(),IF(SUM(B19:K19)=0,1,0)) -> 0 | V19: =IF(ISNA(N19),NA(),IF(SUM(B19:L19)=0,1,0)) -> 0
B20: 1 | C20: 0 | D20: 0 | E20: 0 | F20: 1 | G20: 0 | H20: 0 | I20: 0 | J20: 0 | K20: 0 | L20: 0 | M20: 0 | N20: {=IF(OR(ISNUMBER(FIND(Aux!$D$3:$D$9,_xlfn.TEXTJOIN(,,C20:K20)))),NA(),IF(AND(SUM(C20:F20,H20:K20)=0,G20=1),0,INT((SUMPRODUCT(C20:F20,COLUMN($A$1:$D$1)-1)+SUMPRODUCT(H20:K20,COLUMN($E$1:$H$1)-1))*'Line Follower'!$C$3/SUM(C20:F20,H20:K20)-'Line Follower'!$C$5)))} -> -1 | O20: 1 | P20: =IF(AND(N20=0,G20=1,M20=1),1,0) -> 0 | Q20: =IF(ISERROR(N20),N20,IF(SUM(C20:K20)>=4,1,0)) -> 0 | R20: =IF(AND(B20=1,N20>'Line Follower'!$C$7,SUM(C20:K20)<4),1,0) -> 1 | S20: =IF(AND(L20=1,N20<'Line Follower'!$C$6,SUM(C20:K20)<4),1,0) -> 0 | T20: =IF(ISNA(N20),NA(),IF(SUM(C20:L20)=0,1,0)) -> 0 | U20: =IF(ISNA(N20),NA(),IF(SUM(B20:K20)=0,1,0)) -> 0 | V20: =IF(ISNA(N20),NA(),IF(SUM(B20:L20)=0,1,0)) -> 0
B21: 0 | C21: 1 | D21: 0 | E21: 0 | F21: 1 | G21: 0 | H21: 0 | I21: 0 | J21: 0 | K21: 0 | L21: 0 | M21: 0 | N21: {=IF(OR(ISNUMBER(FIND(Aux!$D$3:$D$9,_xlfn.TEXTJOIN(,,C21:K21)))),NA(),IF(AND(SUM(C21:F21,H21:K21)=0,G21=1),0,INT((SUMPRODUCT(C21:F21,COLUMN($A$1:$D$1)-1)+SUMPRODUCT(H21:K21,COLUMN($E$1:$H$1)-1))*'Line Follower'!$C$3/SUM(C21:F21,H21:K21)-'Line Follower'!$C$5)))} -> #N/A | O21: #N/A | P21: =IF(AND(N21=0,G21=1,M21=1),1,0) -> #N/A | Q21: =IF(ISERROR(N21),N21,IF(SUM(C21:K21)>=4,1,0)) -> #N/A | R21: =IF(AND(B21=1,N21>'Line Follower'!$C$7,SUM(C21:K21)<4),1,0) -> #N/A | S21: =IF(AND(L21=1,N21<'Line Follower'!$C$6,SUM(C21:K21)<4),1,0) -> #N/A | T21: =IF(ISNA(N21),NA(),IF(SUM(C21:L21)=0,1,0)) -> #N/A | U21: =IF(ISNA(N21),NA(),IF(SUM(B21:K21)=0,1,0)) -> #N/A | V21: =IF(ISNA(N21),NA(),IF(SUM(B21:L21)=0,1,0)) -> #N/A
B22: 1 | C22: 1 | D22: 0 | E22: 0 | F22: 1 | G22: 0 | H22: 0 | I22: 0 | J22: 0 | K22: 0 | L22: 0 | M22: 0 | N22: {=IF(OR(ISNUMBER(FIND(Aux!$D$3:$D$9,_xlfn.TEXTJOIN(,,C22:K22)))),NA(),IF(AND(SUM(C22:F22,H22:K22)=0,G22=1),0,INT((SUMPRODUCT(C22:F22,COLUMN($A$1:$D$1)-1)+SUMPRODUCT(H22:K22,COLUMN($E$1:$H$1)-1))*'Line Follower'!$C$3/SUM(C22:F22,H22:K22)-'Line Follower'!$C$5)))} -> #N/A | O22: #N/A | P22: =IF(AND(N22=0,G22=1,M22=1),1,0) -> #N/A | Q22: =IF(ISERROR(N22),N22,IF(SUM(C22:K22)>=4,1,0)) -> #N/A | R22: =IF(AND(B22=1,N22>'Line Follower'!$C$7,SUM(C22:K22)<4),1,0) -> #N/A | S22: =IF(AND(L22=1,N22<'Line Follower'!$C$6,SUM(C22:K22)<4),1,0) -> #N/A | T22: =IF(ISNA(N22),NA(),IF(SUM(C22:L22)=0,1,0)) -> #N/A | U22: =IF(ISNA(N22),NA(),IF(SUM(B22:K22)=0,1,0)) -> #N/A | V22: =IF(ISNA(N22),NA(),IF(SUM(B22:L22)=0,1,0)) -> #N/A
B23: 0 | C23: 0 | D23: 1 | E23: 0 | F23: 1 | G23: 0 | H23: 0 | I23: 0 | J23: 0 | K23: 0 | L23: 0 | M23: 0 | N23: {=IF(OR(ISNUMBER(FIND(Aux!$D$3:$D$9,_xlfn.TEXTJOIN(,,C23:K23)))),NA(),IF(AND(SUM(C23:F23,H23:K23)=0,G23=1),0,INT((SUMPRODUCT(C23:F23,COLUMN($A$1:$D$1)-1)+SUMPRODUCT(H23:K23,COLUMN($E$1:$H$1)-1))*'Line Follower'!$C$3/SUM(C23:F23,H23:K23)-'Line Follower'!$C$5)))} -> #N/A | O23: #N/A | P23: =IF(AND(N23=0,G23=1,M23=1),1,0) -> #N/A | Q23: =IF(ISERROR(N23),N23,IF(SUM(C23:K23)>=4,1,0)) -> #N/A | R23: =IF(AND(B23=1,N23>'Line Follower'!$C$7,SUM(C23:K23)<4),1,0) -> #N/A | S23: =IF(AND(L23=1,N23<'Line Follower'!$C$6,SUM(C23:K23)<4),1,0) -> #N/A | T23: =IF(ISNA(N23),NA(),IF(SUM(C23:L23)=0,1,0)) -> #N/A | U23: =IF(ISNA(N23),NA(),IF(SUM(B23:K23)=0,1,0)) -> #N/A | V23: =IF(ISNA(N23),NA(),IF(SUM(B23:L23)=0,1,0)) -> #N/A
B24: 1 | C24: 0 | D24: 1 | E24: 0 | F24: 1 | G24: 0 | H24: 0 | I24: 0 | J24: 0 | K24: 0 | L24: 0 | M24: 0 | N24: {=IF(OR(ISNUMBER(FIND(Aux!$D$3:$D$9,_xlfn.TEXTJOIN(,,C24:K24)))),NA(),IF(AND(SUM(C24:F24,H24:K24)=0,G24=1),0,INT((SUMPRODUCT(C24:F24,COLUMN($A$1:$D$1)-1)+SUMPRODUCT(H24:K24,COLUMN($E$1:$H$1)-1))*'Line Follower'!$C$3/SUM(C24:F24,H24:K24)-'Line Follower'!$C$5)))} -> #N/A | O24: #N/A | P24: =IF(AND(N24=0,G24=1,M24=1),1,0) -> #N/A | Q24: =IF(ISERROR(N24),N24,IF(SUM(C24:K24)>=4,1,0)) -> #N/A | R24: =IF(AND(B24=1,N24>'Line Follower'!$C$7,SUM(C24:K24)<4),1,0) -> #N/A | S24: =IF(AND(L24=1,N24<'Line Follower'!$C$6,SUM(C24:K24)<4),1,0) -> #N/A | T24: =IF(ISNA(N24),NA(),IF(SUM(C24:L24)=0,1,0)) -> #N/A | U24: =IF(ISNA(N24),NA(),IF(SUM(B24:K24)=0,1,0)) -> #N/A | V24: =IF(ISNA(N24),NA(),IF(SUM(B24:L24)=0,1,0)) -> #N/A
B25: 0 | C25: 1 | D25: 1 | E25: 0 | F25: 1 | G25: 0 | H25: 0 | I25: 0 | J25: 0 | K25: 0 | L25: 0 | M25: 0 | N25: {=IF(OR(ISNUMBER(FIND(Aux!$D$3:$D$9,_xlfn.TEXTJOIN(,,C25:K25)))),NA(),IF(AND(SUM(C25:F25,H25:K25)=0,G25=1),0,INT((SUMPRODUCT(C25:F25,COLUMN($A$1:$D$1)-1)+SUMPRODUCT(H25:K25,COLUMN($E$1:$H$1)-1))*'Line Follower'!$C$3/SUM(C25:F25,H25:K25)-'Line Follower'!$C$5)))} -> #N/A | O25: #N/A | P25: =IF(AND(N25=0,G25=1,M25=1),1,0) -> #N/A | Q25: =IF(ISERROR(N25),N25,IF(SUM(C25:K25)>=4,1,0)) -> #N/A | R25: =IF(AND(B25=1,N25>'Line Follower'!$C$7,SUM(C25:K25)<4),1,0) -> #N/A | S25: =IF(AND(L25=1,N25<'Line Follower'!$C$6,SUM(C25:K25)<4),1,0) -> #N/A | T25: =IF(ISNA(N25),NA(),IF(SUM(C25:L25)=0,1,0)) -> #N/A | U25: =IF(ISNA(N25),NA(),IF(SUM(B25:K25)=0,1,0)) -> #N/A | V25: =IF(ISNA(N25),NA(),IF(SUM(B25:L25)=0,1,0)) -> #N/A
B26: 1 | C26: 1 | D26: 1 | E26: 0 | F26: 1 | G26: 0 | H26: 0 | I26: 0 | J26: 0 | K26: 0 | L26: 0 | M26: 0 | N26: {=IF(OR(ISNUMBER(FIND(Aux!$D$3:$D$9,_xlfn.TEXTJOIN(,,C26:K26)))),NA(),IF(AND(SUM(C26:F26,H26:K26)=0,G26=1),0,INT((SUMPRODUCT(C26:F26,COLUMN($A$1:$D$1)-1)+SUMPRODUCT(H26:K26,COLUMN($E$1:$H$1)-1))*'Line Follower'!$C$3/SUM(C26:F26,H26:K26)-'Line Follower'!$C$5)))} -> #N/A | O26: #N/A | P26: =IF(AND(N26=0,G26=1,M26=1),1,0) -> #N/A | Q26: =IF(ISERROR(N26),N26,IF(SUM(C26:K26)>=4,1,0)) -> #N/A | R26: =IF(AND(B26=1,N26>'Line Follower'!$C$7,SUM(C26:K26)<4),1,0) -> #N/A | S26: =IF(AND(L26=1,N26<'Line Follower'!$C$6,SUM(C26:K26)<4),1,0) -> #N/A | T26: =IF(ISNA(N26),NA(),IF(SUM(C26:L26)=0,1,0)) -> #N/A | U26: =IF(ISNA(N26),NA(),IF(SUM(B26:K26)=0,1,0)) -> #N/A | V26: =IF(ISNA(N26),NA(),IF(SUM(B26:L26)=0,1,0)) -> #N/A
B27: 0 | C27: 0 | D27: 0 | E27: 1 | F27: 1 | G27: 0 | H27: 0 | I27: 0 | J27: 0 | K27: 0 | L27: 0 | M27: 0 | N27: {=IF(OR(ISNUMBER(FIND(Aux!$D$3:$D$9,_xlfn.TEXTJOIN(,,C27:K27)))),NA(),IF(AND(SUM(C27:F27,H27:K27)=0,G27=1),0,INT((SUMPRODUCT(C27:F27,COLUMN($A$1:$D$1)-1)+SUMPRODUCT(H27:K27,COLUMN($E$1:$H$1)-1))*'Line Follower'!$C$3/SUM(C27:F27,H27:K27)-'Line Follower'!$C$5)))} -> -2 | O27: 1 | P27: =IF(AND(N27=0,G27=1,M27=1),1,0) -> 0 | Q27: =IF(ISERROR(N27),N27,IF(SUM(C27:K27)>=4,1,0)) -> 0 | R27: =IF(AND(B27=1,N27>'Line Follower'!$C$7,SUM(C27:K27)<4),1,0) -> 0 | S27: =IF(AND(L27=1,N27<'Line Follower'!$C$6,SUM(C27:K27)<4),1,0) -> 0 | T27: =IF(ISNA(N27),NA(),IF(SUM(C27:L27)=0,1,0)) -> 0 | U27: =IF(ISNA(N27),NA(),IF(SUM(B27:K27)=0,1,0)) -> 0 | V27: =IF(ISNA(N27),NA(),IF(SUM(B27:L27)=0,1,0)) -> 0
B28: 1 | C28: 0 | D28: 0 | E28: 1 | F28: 1 | G28: 0 | H28: 0 | I28: 0 | J28: 0 | K28: 0 | L28: 0 | M28: 0 | N28: {=IF(OR(ISNUMBER(FIND(Aux!$D$3:$D$9,_xlfn.TEXTJOIN(,,C28:K28)))),NA(),IF(AND(SUM(C28:F28,H28:K28)=0,G28=1),0,INT((SUMPRODUCT(C28:F28,COLUMN($A$1:$D$1)-1)+SUMPRODUCT(H28:K28,COLUMN($E$1:$H$1)-1))*'Line Follower'!$C$3/SUM(C28:F28,H28:K28)-'Line Follower'!$C$5)))} -> -2 | O28: 1 | P28: =IF(AND(N28=0,G28=1,M28=1),1,0) -> 0 | Q28: =IF(ISERROR(N28),N28,IF(SUM(C28:K28)>=4,1,0)) -> 0 | R28: =IF(AND(B28=1,N28>'Line Follower'!$C$7,SUM(C28:K28)<4),1,0) -> 1 | S28: =IF(AND(L28=1,N28<'Line Follower'!$C$6,SUM(C28:K28)<4),1,0) -> 0 | T28: =IF(ISNA(N28),NA(),IF(SUM(C28:L28)=0,1,0)) -> 0 | U28: =IF(ISNA(N28),NA(),IF(SUM(B28:K28)=0,1,0)) -> 0 | V28: =IF(ISNA(N28),NA(),IF(SUM(B28:L28)=0,1,0)) -> 0
B29: 0 | C29: 1 | D29: 0 | E29: 1 | F29: 1 | G29: 0 | H29: 0 | I29: 0 | J29: 0 | K29: 0 | L29: 0 | M29: 0 | N29: {=IF(OR(ISNUMBER(FIND(Aux!$D$3:$D$9,_xlfn.TEXTJOIN(,,C29:K29)))),NA(),IF(AND(SUM(C29:F29,H29:K29)=0,G29=1),0,INT((SUMPRODUCT(C29:F29,COLUMN($A$1:$D$1)-1)+SUMPRODUCT(H29:K29,COLUMN($E$1:$H$1)-1))*'Line Follower'!$C$3/SUM(C29:F29,H29:K29)-'Line Follower'!$C$5)))} -> #N/A | O29: #N/A | P29: =IF(AND(N29=0,G29=1,M29=1),1,0) -> #N/A | Q29: =IF(ISERROR(N29),N29,IF(SUM(C29:K29)>=4,1,0)) -> #N/A | R29: =IF(AND(B29=1,N29>'Line Follower'!$C$7,SUM(C29:K29)<4),1,0) -> #N/A | S29: =IF(AND(L29=1,N29<'Line Follower'!$C$6,SUM(C29:K29)<4),1,0) -> #N/A | T29: =IF(ISNA(N29),NA(),IF(SUM(C29:L29)=0,1,0)) -> #N/A | U29: =IF(ISNA(N29),NA(),IF(SUM(B29:K29)=0,1,0)) -> #N/A | V29: =IF(ISNA(N29),NA(),IF(SUM(B29:L29)=0,1,0)) -> #N/A
B30: 1 | C30: 1 | D30: 0 | E30: 1 | F30: 1 | G30: 0 | H30: 0 | I30: 0 | J30: 0 | K30: 0 | L30: 0 | M30: 0 | N30: {=IF(OR(ISNUMBER(FIND(Aux!$D$3:$D$9,_xlfn.TEXTJOIN(,,C30:K30)))),NA(),IF(AND(SUM(C30:F30,H30:K30)=0,G30=1),0,INT((SUMPRODUCT(C30:F30,COLUMN($A$1:$D$1)-1)+SUMPRODUCT(H30:K30,COLUMN($E$1:$H$1)-1))*'Line Follower'!$C$3/SUM(C30:F30,H30:K30)-'Line Follower'!$C$5)))} -> #N/A | O30: #N/A | P30: =IF(AND(N30=0,G30=1,M30=1),1,0) -> #N/A | Q30: =IF(ISERROR(N30),N30,IF(SUM(C30:K30)>=4,1,0)) -> #N/A | R30: =IF(AND(B30=1,N30>'Line Follower'!$C$7,SUM(C30:K30)<4),1,0) -> #N/A | S30: =IF(AND(L30=1,N30<'Line Follower'!$C$6,SUM(C30:K30)<4),1,0) -> #N/A | T30: =IF(ISNA(N30),NA(),IF(SUM(C30:L30)=0,1,0)) -> #N/A | U30: =IF(ISNA(N30),NA(),IF(SUM(B30:K30)=0,1,0)) -> #N/A | V30: =IF(ISNA(N30),NA(),IF(SUM(B30:L30)=0,1,0)) -> #N/A
B31: 0 | C31: 0 | D31: 1 | E31: 1 | F31: 1 | G31: 0 | H31: 0 | I31: 0 | J31: 0 | K31: 0 | L31: 0 | M31: 0 | N31: {=IF(OR(ISNUMBER(FIND(Aux!$D$3:$D$9,_xlfn.TEXTJOIN(,,C31:K31)))),NA(),IF(AND(SUM(C31:F31,H31:K31)=0,G31=1),0,INT((SUMPRODUCT(C31:F31,COLUMN($A$1:$D$1)-1)+SUMPRODUCT(H31:K31,COLUMN($E$1:$H$1)-1))*'Line Follower'!$C$3/SUM(C31:F31,H31:K31)-'Line Follower'!$C$5)))} -> -3 | O31: 1 | P31: =IF(AND(N31=0,G31=1,M31=1),1,0) -> 0 | Q31: =IF(ISERROR(N31),N31,IF(SUM(C31:K31)>=4,1,0)) -> 0 | R31: =IF(AND(B31=1,N31>'Line Follower'!$C$7,SUM(C31:K31)<4),1,0) -> 0 | S31: =IF(AND(L31=1,N31<'Line Follower'!$C$6,SUM(C31:K31)<4),1,0) -> 0 | T31: =IF(ISNA(N31),NA(),IF(SUM(C31:L31)=0,1,0)) -> 0 | U31: =IF(ISNA(N31),NA(),IF(SUM(B31:K31)=0,1,0)) -> 0 | V31: =IF(ISNA(N31),NA(),IF(SUM(B31:L31)=0,1,0)) -> 0
B32: 1 | C32: 0 | D32: 1 | E32: 1 | F32: 1 | G32: 0 | H32: 0 | I32: 0 | J32: 0 | K32: 0 | L32: 0 | M32: 0 | N32: {=IF(OR(ISNUMBER(FIND(Aux!$D$3:$D$9,_xlfn.TEXTJOIN(,,C32:K32)))),NA(),IF(AND(SUM(C32:F32,H32:K32)=0,G32=1),0,INT((SUMPRODUCT(C32:F32,COLUMN($A$1:$D$1)-1)+SUMPRODUCT(H32:K32,COLUMN($E$1:$H$1)-1))*'Line Follower'!$C$3/SUM(C32:F32,H32:K32)-'Line Follower'!$C$5)))} -> -3 | O32: 1 | P32: =IF(AND(N32=0,G32=1,M32=1),1,0) -> 0 | Q32: =IF(ISERROR(N32),N32,IF(SUM(C32:K32)>=4,1,0)) -> 0 | R32: =IF(AND(B32=1,N32>'Line Follower'!$C$7,SUM(C32:K32)<4),1,0) -> 1 | S32: =IF(AND(L32=1,N32<'Line Follower'!$C$6,SUM(C32:K32)<4),1,0) -> 0 | T32: =IF(ISNA(N32),NA(),IF(SUM(C32:L32)=0,1,0)) -> 0 | U32: =IF(ISNA(N32),NA(),IF(SUM(B32:K32)=0,1,0)) -> 0 | V32: =IF(ISNA(N32),NA(),IF(SUM(B32:L32)=0,1,0)) -> 0
B33: 0 | C33: 1 | D33: 1 | E33: 1 | F33: 1 | G33: 0 | H33: 0 | I33: 0 | J33: 0 | K33: 0 | L33: 0 | M33: 0 | N33: {=IF(OR(ISNUMBER(FIND(Aux!$D$3:$D$9,_xlfn.TEXTJOIN(,,C33:K33)))),NA(),IF(AND(SUM(C33:F33,H33:K33)=0,G33=1),0,INT((SUMPRODUCT(C33:F33,COLUMN($A$1:$D$1)-1)+SUMPRODUCT(H33:K33,COLUMN($E$1:$H$1)-1))*'Line Follower'!$C$3/SUM(C33:F33,H33:K33)-'Line Follower'!$C$5)))} -> -4 | O33: 1 | P33: =IF(AND(N33=0,G33=1,M33=1),1,0) -> 0 | Q33: =IF(ISERROR(N33),N33,IF(SUM(C33:K33)>=4,1,0)) -> 1 | R33: =IF(AND(B33=1,N33>'Line Follower'!$C$7,SUM(C33:K33)<4),1,0) -> 0 | S33: =IF(AND(L33=1,N33<'Line Follower'!$C$6,SUM(C33:K33)<4),1,0) -> 0 | T33: =IF(ISNA(N33),NA(),IF(SUM(C33:L33)=0,1,0)) -> 0 | U33: =IF(ISNA(N33),NA(),IF(SUM(B33:K33)=0,1,0)) -> 0 | V33: =IF(ISNA(N33),NA(),IF(SUM(B33:L33)=0,1,0)) -> 0
B34: 1 | C34: 1 | D34: 1 | E34: 1 | F34: 1 | G34: 0 | H34: 0 | I34: 0 | J34: 0 | K34: 0 | L34: 0 | M34: 0 | N34: {=IF(OR(ISNUMBER(FIND(Aux!$D$3:$D$9,_xlfn.TEXTJOIN(,,C34:K34)))),NA(),IF(AND(SUM(C34:F34,H34:K34)=0,G34=1),0,INT((SUMPRODUCT(C34:F34,COLUMN($A$1:$D$1)-1)+SUMPRODUCT(H34:K34,COLUMN($E$1:$H$1)-1))*'Line Follower'!$C$3/SUM(C34:F34,H34:K34)-'Line Follower'!$C$5)))} -> -4 | O34: 1 | P34: =IF(AND(N34=0,G34=1,M34=1),1,0) -> 0 | Q34: =IF(ISERROR(N34),N34,IF(SUM(C34:K34)>=4,1,0)) -> 1 | R34: =IF(AND(B34=1,N34>'Line Follower'!$C$7,SUM(C34:K34)<4),1,0) -> 0 | S34: =IF(AND(L34=1,N34<'Line Follower'!$C$6,SUM(C34:K34)<4),1,0) -> 0 | T34: =IF(ISNA(N34),NA(),IF(SUM(C34:L34)=0,1,0)) -> 0 | U34: =IF(ISNA(N34),NA(),IF(SUM(B34:K34)=0,1,0)) -> 0 | V34: =IF(ISNA(N34),NA(),IF(SUM(B34:L34)=0,1,0)) -> 0
B35: 0 | C35: 0 | D35: 0 | E35: 0 | F35: 0 | G35: 1 | H35: 0 | I35: 0 | J35: 0 | K35: 0 | L35: 0 | M35: 0 | N35: {=IF(OR(ISNUMBER(FIND(Aux!$D$3:$D$9,_xlfn.TEXTJOIN(,,C35:K35)))),NA(),IF(AND(SUM(C35:F35,H35:K35)=0,G35=1),0,INT((SUMPRODUCT(C35:F35,COLUMN($A$1:$D$1)-1)+SUMPRODUCT(H35:K35,COLUMN($E$1:$H$1)-1))*'Line Follower'!$C$3/SUM(C35:F35,H35:K35)-'Line Follower'!$C$5)))} -> 0 | O35: 1 | P35: =IF(AND(N35=0,G35=1,M35=1),1,0) -> 0 | Q35: =IF(ISERROR(N35),N35,IF(SUM(C35:K35)>=4,1,0)) -> 0 | R35: =IF(AND(B35=1,N35>'Line Follower'!$C$7,SUM(C35:K35)<4),1,0) -> 0 | S35: =IF(AND(L35=1,N35<'Line Follower'!$C$6,SUM(C35:K35)<4),1,0) -> 0 | T35: =IF(ISNA(N35),NA(),IF(SUM(C35:L35)=0,1,0)) -> 0 | U35: =IF(ISNA(N35),NA(),IF(SUM(B35:K35)=0,1,0)) -> 0 | V35: =IF(ISNA(N35),NA(),IF(SUM(B35:L35)=0,1,0)) -> 0
B36: 1 | C36: 0 | D36: 0 | E36: 0 | F36: 0 | G36: 1 | H36: 0 | I36: 0 | J36: 0 | K36: 0 | L36: 0 | M36: 0 | N36: {=IF(OR(ISNUMBER(FIND(Aux!$D$3:$D$9,_xlfn.TEXTJOIN(,,C36:K36)))),NA(),IF(AND(SUM(C36:F36,H36:K36)=0,G36=1),0,INT((SUMPRODUCT(C36:F36,COLUMN($A$1:$D$1)-1)+SUMPRODUCT(H36:K36,COLUMN($E$1:$H$1)-1))*'Line Follower'!$C$3/SUM(C36:F36,H36:K36)-'Line Follower'!$C$5)))} -> 0 | O36: 1 | P36: =IF(AND(N36=0,G36=1,M36=1),1,0) -> 0 | Q36: =IF(ISERROR(N36),N36,IF(SUM(C36:K36)>=4,1,0)) -> 0 | R36: =IF(AND(B36=1,N36>'Line Follower'!$C$7,SUM(C36:K36)<4),1,0) -> 1 | S36: =IF(AND(L36=1,N36<'Line Follower'!$C$6,SUM(C36:K36)<4),1,0) -> 0 | T36: =IF(ISNA(N36),NA(),IF(SUM(C36:L36)=0,1,0)) -> 0 | U36: =IF(ISNA(N36),NA(),IF(SUM(B36:K36)=0,1,0)) -> 0 | V36: =IF(ISNA(N36),NA(),IF(SUM(B36:L36)=0,1,0)) -> 0
B37: 0 | C37: 1 | D37: 0 | E37: 0 | F37: 0 | G37: 1 | H37: 0 | I37: 0 | J37: 0 | K37: 0 | L37: 0 | M37: 0 | N37: {=IF(OR(ISNUMBER(FIND(Aux!$D$3:$D$9,_xlfn.TEXTJOIN(,,C37:K37)))),NA(),IF(AND(SUM(C37:F37,H37:K37)=0,G37=1),0,INT((SUMPRODUCT(C37:F37,COLUMN($A$1:$D$1)-1)+SUMPRODUCT(H37:K37,COLUMN($E$1:$H$1)-1))*'Line Follower'!$C$3/SUM(C37:F37,H37:K37)-'Line Follower'!$C$5)))} -> #N/A | O37: #N/A | P37: =IF(AND(N37=0,G37=1,M37=1),1,0) -> #N/A | Q37: =IF(ISERROR(N37),N37,IF(SUM(C37:K37)>=4,1,0)) -> #N/A | R37: =IF(AND(B37=1,N37>'Line Follower'!$C$7,SUM(C37:K37)<4),1,0) -> #N/A | S37: =IF(AND(L37=1,N37<'Line Follower'!$C$6,SUM(C37:K37)<4),1,0) -> #N/A | T37: =IF(ISNA(N37),NA(),IF(SUM(C37:L37)=0,1,0)) -> #N/A | U37: =IF(ISNA(N37),NA(),IF(SUM(B37:K37)=0,1,0)) -> #N/A | V37: =IF(ISNA(N37),NA(),IF(SUM(B37:L37)=0,1,0)) -> #N/A
B38: 1 | C38: 1 | D38: 0 | E38: 0 | F38: 0 | G38: 1 | H38: 0 | I38: 0 | J38: 0 | K38: 0 | L38: 0 | M38: 0 | N38: {=IF(OR(ISNUMBER(FIND(Aux!$D$3:$D$9,_xlfn.TEXTJOIN(,,C38:K38)))),NA(),IF(AND(SUM(C38:F38,H38:K38)=0,G38=1),0,INT((SUMPRODUCT(C38:F38,COLUMN($A$1:$D$1)-1)+SUMPRODUCT(H38:K38,COLUMN($E$1:$H$1)-1))*'Line Follower'!$C$3/SUM(C38:F38,H38:K38)-'Line Follower'!$C$5)))} -> #N/A | O38: #N/A | P38: =IF(AND(N38=0,G38=1,M38=1),1,0) -> #N/A | Q38: =IF(ISERROR(N38),N38,IF(SUM(C38:K38)>=4,1,0)) -> #N/A | R38: =IF(AND(B38=1,N38>'Line Follower'!$C$7,SUM(C38:K38)<4),1,0) -> #N/A | S38: =IF(AND(L38=1,N38<'Line Follower'!$C$6,SUM(C38:K38)<4),1,0) -> #N/A | T38: =IF(ISNA(N38),NA(),IF(SUM(C38:L38)=0,1,0)) -> #N/A | U38: =IF(ISNA(N38),NA(),IF(SUM(B38:K38)=0,1,0)) -> #N/A | V38: =IF(ISNA(N38),NA(),IF(SUM(B38:L38)=0,1,0)) -> #N/A
B39: 0 | C39: 0 | D39: 1 | E39: 0 | F39: 0 | G39: 1 | H39: 0 | I39: 0 | J39: 0 | K39: 0 | L39: 0 | M39: 0 | N39: {=IF(OR(ISNUMBER(FIND(Aux!$D$3:$D$9,_xlfn.TEXTJOIN(,,C39:K39)))),NA(),IF(AND(SUM(C39:F39,H39:K39)=0,G39=1),0,INT((SUMPRODUCT(C39:F39,COLUMN($A$1:$D$1)-1)+SUMPRODUCT(H39:K39,COLUMN($E$1:$H$1)-1))*'Line Follower'!$C$3/SUM(C39:F39,H39:K39)-'Line Follower'!$C$5)))} -> #N/A | O39: #N/A | P39: =IF(AND(N39=0,G39=1,M39=1),1,0) -> #N/A | Q39: =IF(ISERROR(N39),N39,IF(SUM(C39:K39)>=4,1,0)) -> #N/A | R39: =IF(AND(B39=1,N39>'Line Follower'!$C$7,SUM(C39:K39)<4),1,0) -> #N/A | S39: =IF(AND(L39=1,N39<'Line Follower'!$C$6,SUM(C39:K39)<4),1,0) -> #N/A | T39: =IF(ISNA(N39),NA(),IF(SUM(C39:L39)=0,1,0)) -> #N/A | U39: =IF(ISNA(N39),NA(),IF(SUM(B39:K39)=0,1,0)) -> #N/A | V39: =IF(ISNA(N39),NA(),IF(SUM(B39:L39)=0,1,0)) -> #N/A
B40: 1 | C40: 0 | D40: 1 | E40: 0 | F40: 0 | G40: 1 | H40: 0 | I40: 0 | J40: 0 | K40: 0 | L40: 0 | M40: 0 | N40: {=IF(OR(ISNUMBER(FIND(Aux!$D$3:$D$9,_xlfn.TEXTJOIN(,,C40:K40)))),NA(),IF(AND(SUM(C40:F40,H40:K40)=0,G40=1),0,INT((SUMPRODUCT(C40:F40,COLUMN($A$1:$D$1)-1)+SUMPRODUCT(H40:K40,COLUMN($E$1:$H$1)-1))*'Line Follower'!$C$3/SUM(C40:F40,H40:K40)-'Line Follower'!$C$5)))} -> #N/A | O40: #N/A | P40: =IF(AND(N40=0,G40=1,M40=1),1,0) -> #N/A | Q40: =IF(ISERROR(N40),N40,IF(SUM(C40:K40)>=4,1,0)) -> #N/A | R40: =IF(AND(B40=1,N40>'Line Follower'!$C$7,SUM(C40:K40)<4),1,0) -> #N/A | S40: =IF(AND(L40=1,N40<'Line Follower'!$C$6,SUM(C40:K40)<4),1,0) -> #N/A | T40: =IF(ISNA(N40),NA(),IF(SUM(C40:L40)=0,1,0)) -> #N/A | U40: =IF(ISNA(N40),NA(),IF(SUM(B40:K40)=0,1,0)) -> #N/A | V40: =IF(ISNA(N40),NA(),IF(SUM(B40:L40)=0,1,0)) -> #N/A
B41: 0 | C41: 1 | D41: 1 | E41: 0 | F41: 0 | G41: 1 | H41: 0 | I41: 0 | J41: 0 | K41: 0 | L41: 0 | M41: 0 | N41: {=IF(OR(ISNUMBER(FIND(Aux!$D$3:$D$9,_xlfn.TEXTJOIN(,,C41:K41)))),NA(),IF(AND(SUM(C41:F41,H41:K41)=0,G41=1),0,INT((SUMPRODUCT(C41:F41,COLUMN($A$1:$D$1)-1)+SUMPRODUCT(H41:K41,COLUMN($E$1:$H$1)-1))*'Line Follower'!$C$3/SUM(C41:F41,H41:K41)-'Line Follower'!$C$5)))} -> #N/A | O41: #N/A | P41: =IF(AND(N41=0,G41=1,M41=1),1,0) -> #N/A | Q41: =IF(ISERROR(N41),N41,IF(SUM(C41:K41)>=4,1,0)) -> #N/A | R41: =IF(AND(B41=1,N41>'Line Follower'!$C$7,SUM(C41:K41)<4),1,0) -> #N/A | S41: =IF(AND(L41=1,N41<'Line Follower'!$C$6,SUM(C41:K41)<4),1,0) -> #N/A | T41: =IF(ISNA(N41),NA(),IF(SUM(C41:L41)=0,1,0)) -> #N/A | U41: =IF(ISNA(N41),NA(),IF(SUM(B41:K41)=0,1,0)) -> #N/A | V41: =IF(ISNA(N41),NA(),IF(SUM(B41:L41)=0,1,0)) -> #N/A
...

Sheet Track Observer
B2: Index | C2: Timestamp | D2: Left | E2: IR2 | F2: IR3 | G2: IR4 | H2: IR5 | I2: Center | J2: IR8 | K2: IR9 | L2: IR10 | M2: IR11 | N2: Right | O2: Middle | P2: Last Error | Q2: line | R2: straight | S2: crossing | T2: curve | U2: marker | V2: left | W2: right | X2: pitch | Y2: ANY
B3: 0 | C3: 0 | D3: 0 | E3: 0 | F3: 0 | G3: 0 | H3: 1 | I3: 1 | J3: 0 | K3: 0 | L3: 0 | M3: 0 | N3: 0 | O3: 1 | P3: 0 | Q3: {=IFERROR(_xlfn.XLOOKUP(_xlfn.TEXTJOIN(,,D3:O3),Aux!$B$3:$B$4098,'Truth Table'!$O$3:$S$4098)=1,FALSE)} -> TRUE | R3: FALSE | S3: FALSE | T3: FALSE | U3: FALSE | V3: =AND(_xlfn.XLOOKUP(_xlfn.TEXTJOIN(,,D3:O3),Aux!$B$3:$B$4098,'Truth Table'!$T$3:$T$4098)=1,P2<='Line Follower'!$C$7) -> FALSE | W3: =AND(_xlfn.XLOOKUP(_xlfn.TEXTJOIN(,,D3:O3),Aux!$B$3:$B$4098,'Truth Table'!$U$3:$U$4098)=1,P2>='Line Follower'!$C$6) -> FALSE | X3: =IFERROR(AND(_xlfn.XLOOKUP(_xlfn.TEXTJOIN(,,D3:O3),Aux!$B$3:$B$4098,'Truth Table'!$V$3:$V$4098)=1,ABS(P2)<='Line Follower'!$C$6),FALSE) -> FALSE | Y3: =OR(Q3:X3) -> TRUE
B4: 1 | C4: 0 | D4: 0 | E4: 0 | F4: 0 | G4: 0 | H4: 1 | I4: 1 | J4: 0 | K4: 0 | L4: 0 | M4: 0 | N4: 0 | O4: 1 | P4: =IFERROR(_xlfn.XLOOKUP(_xlfn.TEXTJOIN(,,D3:O3),Aux!$B$3:$B$4098,'Truth Table'!$N$3:$N$4098),P3) -> -1 | Q4: {=IFERROR(_xlfn.XLOOKUP(_xlfn.TEXTJOIN(,,D4:O4),Aux!$B$3:$B$4098,'Truth Table'!$O$3:$S$4098)=1,FALSE)} -> TRUE | R4: FALSE | S4: FALSE | T4: FALSE | U4: FALSE | V4: =AND(_xlfn.XLOOKUP(_xlfn.TEXTJOIN(,,D4:O4),Aux!$B$3:$B$4098,'Truth Table'!$T$3:$T$4098)=1,P3<='Line Follower'!$C$7) -> FALSE | W4: =AND(_xlfn.XLOOKUP(_xlfn.TEXTJOIN(,,D4:O4),Aux!$B$3:$B$4098,'Truth Table'!$U$3:$U$4098)=1,P3>='Line Follower'!$C$6) -> FALSE | X4: =IFERROR(AND(_xlfn.XLOOKUP(_xlfn.TEXTJOIN(,,D4:O4),Aux!$B$3:$B$4098,'Truth Table'!$V$3:$V$4098)=1,ABS(P3)<='Line Follower'!$C$6),FALSE) -> FALSE | Y4: =OR(Q4:X4) -> TRUE
B5: 2 | C5: 0 | D5: 0 | E5: 0 | F5: 0 | G5: 0 | H5: 1 | I5: 1 | J5: 0 | K5: 0 | L5: 0 | M5: 0 | N5: 0 | O5: 1 | P5: =IFERROR(_xlfn.XLOOKUP(_xlfn.TEXTJOIN(,,D4:O4),Aux!$B$3:$B$4098,'Truth Table'!$N$3:$N$4098),P4) -> -1 | Q5: {=IFERROR(_xlfn.XLOOKUP(_xlfn.TEXTJOIN(,,D5:O5),Aux!$B$3:$B$4098,'Truth Table'!$O$3:$S$4098)=1,FALSE)} -> TRUE | R5: FALSE | S5: FALSE | T5: FALSE | U5: FALSE | V5: =AND(_xlfn.XLOOKUP(_xlfn.TEXTJOIN(,,D5:O5),Aux!$B$3:$B$4098,'Truth Table'!$T$3:$T$4098)=1,P4<='Line Follower'!$C$7) -> FALSE | W5: =AND(_xlfn.XLOOKUP(_xlfn.TEXTJOIN(,,D5:O5),Aux!$B$3:$B$4098,'Truth Table'!$U$3:$U$4098)=1,P4>='Line Follower'!$C$6) -> FALSE | X5: =IFERROR(AND(_xlfn.XLOOKUP(_xlfn.TEXTJOIN(,,D5:O5),Aux!$B$3:$B$4098,'Truth Table'!$V$3:$V$4098)=1,ABS(P4)<='Line Follower'!$C$6),FALSE) -> FALSE | Y5: =OR(Q5:X5) -> TRUE
B6: 3 | C6: 0 | D6: 0 | E6: 0 | F6: 0 | G6: 0 | H6: 1 | I6: 1 | J6: 0 | K6: 0 | L6: 0 | M6: 0 | N6: 0 | O6: 1 | P6: =IFERROR(_xlfn.XLOOKUP(_xlfn.TEXTJOIN(,,D5:O5),Aux!$B$3:$B$4098,'Truth Table'!$N$3:$N$4098),P5) -> -1 | Q6: {=IFERROR(_xlfn.XLOOKUP(_xlfn.TEXTJOIN(,,D6:O6),Aux!$B$3:$B$4098,'Truth Table'!$O$3:$S$4098)=1,FALSE)} -> TRUE | R6: FALSE | S6: FALSE | T6: FALSE | U6: FALSE | V6: =AND(_xlfn.XLOOKUP(_xlfn.TEXTJOIN(,,D6:O6),Aux!$B$3:$B$4098,'Truth Table'!$T$3:$T$4098)=1,P5<='Line Follower'!$C$7) -> FALSE | W6: =AND(_xlfn.XLOOKUP(_xlfn.TEXTJOIN(,,D6:O6),Aux!$B$3:$B$4098,'Truth Table'!$U$3:$U$4098)=1,P5>='Line Follower'!$C$6) -> FALSE | X6: =IFERROR(AND(_xlfn.XLOOKUP(_xlfn.TEXTJOIN(,,D6:O6),Aux!$B$3:$B$4098,'Truth Table'!$V$3:$V$4098)=1,ABS(P5)<='Line Follower'!$C$6),FALSE) -> FALSE | Y6: =OR(Q6:X6) -> TRUE
B7: 4 | C7: 0 | D7: 0 | E7: 0 | F7: 0 | G7: 0 | H7: 1 | I7: 1 | J7: 0 | K7: 0 | L7: 0 | M7: 0 | N7: 0 | O7: 1 | P7: =IFERROR(_xlfn.XLOOKUP(_xlfn.TEXTJOIN(,,D6:O6),Aux!$B$3:$B$4098,'Truth Table'!$N$3:$N$4098),P6) -> -1 | Q7: {=IFERROR(_xlfn.XLOOKUP(_xlfn.TEXTJOIN(,,D7:O7),Aux!$B$3:$B$4098,'Truth Table'!$O$3:$S$4098)=1,FALSE)} -> TRUE | R7: FALSE | S7: FALSE | T7: FALSE | U7: FALSE | V7: =AND(_xlfn.XLOOKUP(_xlfn.TEXTJOIN(,,D7:O7),Aux!$B$3:$B$4098,'Truth Table'!$T$3:$T$4098)=1,P6<='Line Follower'!$C$7) -> FALSE | W7: =AND(_xlfn.XLOOKUP(_xlfn.TEXTJOIN(,,D7:O7),Aux!$B$3:$B$4098,'Truth Table'!$U$3:$U$4098)=1,P6>='Line Follower'!$C$6) -> FALSE | X7: =IFERROR(AND(_xlfn.XLOOKUP(_xlfn.TEXTJOIN(,,D7:O7),Aux!$B$3:$B$4098,'Truth Table'!$V$3:$V$4098)=1,ABS(P6)<='Line Follower'!$C$6),FALSE) -> FALSE | Y7: =OR(Q7:X7) -> TRUE
B8: 5 | C8: 0 | D8: 0 | E8: 0 | F8: 0 | G8: 0 | H8: 1 | I8: 1 | J8: 0 | K8: 0 | L8: 0 | M8: 0 | N8: 0 | O8: 1 | P8: =IFERROR(_xlfn.XLOOKUP(_xlfn.TEXTJOIN(,,D7:O7),Aux!$B$3:$B$4098,'Truth Table'!$N$3:$N$4098),P7) -> -1 | Q8: {=IFERROR(_xlfn.XLOOKUP(_xlfn.TEXTJOIN(,,D8:O8),Aux!$B$3:$B$4098,'Truth Table'!$O$3:$S$4098)=1,FALSE)} -> TRUE | R8: FALSE | S8: FALSE | T8: FALSE | U8: FALSE | V8: =AND(_xlfn.XLOOKUP(_xlfn.TEXTJOIN(,,D8:O8),Aux!$B$3:$B$4098,'Truth Table'!$T$3:$T$4098)=1,P7<='Line Follower'!$C$7) -> FALSE | W8: =AND(_xlfn.XLOOKUP(_xlfn.TEXTJOIN(,,D8:O8),Aux!$B$3:$B$4098,'Truth Table'!$U$3:$U$4098)=1,P7>='Line Follower'!$C$6) -> FALSE | X8: =IFERROR(AND(_xlfn.XLOOKUP(_xlfn.TEXTJOIN(,,D8:O8),Aux!$B$3:$B$4098,'Truth Table'!$V$3:$V$4098)=1,ABS(P7)<='Line Follower'!$C$6),FALSE) -> FALSE | Y8: =OR(Q8:X8) -> TRUE
B9: 6 | C9: 0 | D9: 0 | E9: 0 | F9: 0 | G9: 0 | H9: 1 | I9: 1 | J9: 0 | K9: 0 | L9: 0 | M9: 0 | N9: 0 | O9: 1 | P9: =IFERROR(_xlfn.XLOOKUP(_xlfn.TEXTJOIN(,,D8:O8),Aux!$B$3:$B$4098,'Truth Table'!$N$3:$N$4098),P8) -> -1 | Q9: {=IFERROR(_xlfn.XLOOKUP(_xlfn.TEXTJOIN(,,D9:O9),Aux!$B$3:$B$4098,'Truth Table'!$O$3:$S$4098)=1,FALSE)} -> TRUE | R9: FALSE | S9: FALSE | T9: FALSE | U9: FALSE | V9: =AND(_xlfn.XLOOKUP(_xlfn.TEXTJOIN(,,D9:O9),Aux!$B$3:$B$4098,'Truth Table'!$T$3:$T$4098)=1,P8<='Line Follower'!$C$7) -> FALSE | W9: =AND(_xlfn.XLOOKUP(_xlfn.TEXTJOIN(,,D9:O9),Aux!$B$3:$B$4098,'Truth Table'!$U$3:$U$4098)=1,P8>='Line Follower'!$C$6) -> FALSE | X9: =IFERROR(AND(_xlfn.XLOOKUP(_xlfn.TEXTJOIN(,,D9:O9),Aux!$B$3:$B$4098,'Truth Table'!$V$3:$V$4098)=1,ABS(P8)<='Line Follower'!$C$6),FALSE) -> FALSE | Y9: =OR(Q9:X9) -> TRUE
B10: 7 | C10: 0 | D10: 0 | E10: 0 | F10: 0 | G10: 0 | H10: 1 | I10: 1 | J10: 0 | K10: 0 | L10: 0 | M10: 0 | N10: 0 | O10: 1 | P10: =IFERROR(_xlfn.XLOOKUP(_xlfn.TEXTJOIN(,,D9:O9),Aux!$B$3:$B$4098,'Truth Table'!$N$3:$N$4098),P9) -> -1 | Q10: {=IFERROR(_xlfn.XLOOKUP(_xlfn.TEXTJOIN(,,D10:O10),Aux!$B$3:$B$4098,'Truth Table'!$O$3:$S$4098)=1,FALSE)} -> TRUE | R10: FALSE | S10: FALSE | T10: FALSE | U10: FALSE | V10: =AND(_xlfn.XLOOKUP(_xlfn.TEXTJOIN(,,D10:O10),Aux!$B$3:$B$4098,'Truth Table'!$T$3:$T$4098)=1,P9<='Line Follower'!$C$7) -> FALSE | W10: =AND(_xlfn.XLOOKUP(_xlfn.TEXTJOIN(,,D10:O10),Aux!$B$3:$B$4098,'Truth Table'!$U$3:$U$4098)=1,P9>='Line Follower'!$C$6) -> FALSE | X10: =IFERROR(AND(_xlfn.XLOOKUP(_xlfn.TEXTJOIN(,,D10:O10),Aux!$B$3:$B$4098,'Truth Table'!$V$3:$V$4098)=1,ABS(P9)<='Line Follower'!$C$6),FALSE) -> FALSE | Y10: =OR(Q10:X10) -> TRUE
B11: 8 | C11: 0 | D11: 0 | E11: 0 | F11: 0 | G11: 0 | H11: 1 | I11: 1 | J11: 0 | K11: 0 | L11: 0 | M11: 0 | N11: 0 | O11: 1 | P11: =IFERROR(_xlfn.XLOOKUP(_xlfn.TEXTJOIN(,,D10:O10),Aux!$B$3:$B$4098,'Truth Table'!$N$3:$N$4098),P10) -> -1 | Q11: {=IFERROR(_xlfn.XLOOKUP(_xlfn.TEXTJOIN(,,D11:O11),Aux!$B$3:$B$4098,'Truth Table'!$O$3:$S$4098)=1,FALSE)} -> TRUE | R11: FALSE | S11: FALSE | T11: FALSE | U11: FALSE | V11: =AND(_xlfn.XLOOKUP(_xlfn.TEXTJOIN(,,D11:O11),Aux!$B$3:$B$4098,'Truth Table'!$T$3:$T$4098)=1,P10<='Line Follower'!$C$7) -> FALSE | W11: =AND(_xlfn.XLOOKUP(_xlfn.TEXTJOIN(,,D11:O11),Aux!$B$3:$B$4098,'Truth Table'!$U$3:$U$4098)=1,P10>='Line Follower'!$C$6) -> FALSE | X11: =IFERROR(AND(_xlfn.XLOOKUP(_xlfn.TEXTJOIN(,,D11:O11),Aux!$B$3:$B$4098,'Truth Table'!$V$3:$V$4098)=1,ABS(P10)<='Line Follower'!$C$6),FALSE) -> FALSE | Y11: =OR(Q11:X11) -> TRUE
B12: 9 | C12: 0 | D12: 0 | E12: 0 | F12: 0 | G12: 0 | H12: 1 | I12: 1 | J12: 0 | K12: 0 | L12: 0 | M12: 0 | N12: 0 | O12: 1 | P12: =IFERROR(_xlfn.XLOOKUP(_xlfn.TEXTJOIN(,,D11:O11),Aux!$B$3:$B$4098,'Truth Table'!$N$3:$N$4098),P11) -> -1 | Q12: {=IFERROR(_xlfn.XLOOKUP(_xlfn.TEXTJOIN(,,D12:O12),Aux!$B$3:$B$4098,'Truth Table'!$O$3:$S$4098)=1,FALSE)} -> TRUE | R12: FALSE | S12: FALSE | T12: FALSE | U12: FALSE | V12: =AND(_xlfn.XLOOKUP(_xlfn.TEXTJOIN(,,D12:O12),Aux!$B$3:$B$4098,'Truth Table'!$T$3:$T$4098)=1,P11<='Line Follower'!$C$7) -> FALSE | W12: =AND(_xlfn.XLOOKUP(_xlfn.TEXTJOIN(,,D12:O12),Aux!$B$3:$B$4098,'Truth Table'!$U$3:$U$4098)=1,P11>='Line Follower'!$C$6) -> FALSE | X12: =IFERROR(AND(_xlfn.XLOOKUP(_xlfn.TEXTJOIN(,,D12:O12),Aux!$B$3:$B$4098,'Truth Table'!$V$3:$V$4098)=1,ABS(P11)<='Line Follower'!$C$6),FALSE) -> FALSE | Y12: =OR(Q12:X12) -> TRUE
B13: 10 | C13: 0 | D13: 0 | E13: 0 | F13: 0 | G13: 0 | H13: 1 | I13: 1 | J13: 0 | K13: 0 | L13: 0 | M13: 0 | N13: 0 | O13: 1 | P13: =IFERROR(_xlfn.XLOOKUP(_xlfn.TEXTJOIN(,,D12:O12),Aux!$B$3:$B$4098,'Truth Table'!$N$3:$N$4098),P12) -> -1 | Q13: {=IFERROR(_xlfn.XLOOKUP(_xlfn.TEXTJOIN(,,D13:O13),Aux!$B$3:$B$4098,'Truth Table'!$O$3:$S$4098)=1,FALSE)} -> TRUE | R13: FALSE | S13: FALSE | T13: FALSE | U13: FALSE | V13: =AND(_xlfn.XLOOKUP(_xlfn.TEXTJOIN(,,D13:O13),Aux!$B$3:$B$4098,'Truth Table'!$T$3:$T$4098)=1,P12<='Line Follower'!$C$7) -> FALSE | W13: =AND(_xlfn.XLOOKUP(_xlfn.TEXTJOIN(,,D13:O13),Aux!$B$3:$B$4098,'Truth Table'!$U$3:$U$4098)=1,P12>='Line Follower'!$C$6) -> FALSE | X13: =IFERROR(AND(_xlfn.XLOOKUP(_xlfn.TEXTJOIN(,,D13:O13),Aux!$B$3:$B$4098,'Truth Table'!$V$3:$V$4098)=1,ABS(P12)<='Line Follower'!$C$6),FALSE) -> FALSE | Y13: =OR(Q13:X13) -> TRUE
B14: 11 | C14: 0 | D14: 0 | E14: 0 | F14: 0 | G14: 0 | H14: 1 | I14: 1 | J14: 0 | K14: 0 | L14: 0 | M14: 0 | N14: 0 | O14: 1 | P14: =IFERROR(_xlfn.XLOOKUP(_xlfn.TEXTJOIN(,,D13:O13),Aux!$B$3:$B$4098,'Truth Table'!$N$3:$N$4098),P13) -> -1 | Q14: {=IFERROR(_xlfn.XLOOKUP(_xlfn.TEXTJOIN(,,D14:O14),Aux!$B$3:$B$4098,'Truth Table'!$O$3:$S$4098)=1,FALSE)} -> TRUE | R14: FALSE | S14: FALSE | T14: FALSE | U14: FALSE | V14: =AND(_xlfn.XLOOKUP(_xlfn.TEXTJOIN(,,D14:O14),Aux!$B$3:$B$4098,'Truth Table'!$T$3:$T$4098)=1,P13<='Line Follower'!$C$7) -> FALSE | W14: =AND(_xlfn.XLOOKUP(_xlfn.TEXTJOIN(,,D14:O14),Aux!$B$3:$B$4098,'Truth Table'!$U$3:$U$4098)=1,P13>='Line Follower'!$C$6) -> FALSE | X14: =IFERROR(AND(_xlfn.XLOOKUP(_xlfn.TEXTJOIN(,,D14:O14),Aux!$B$3:$B$4098,'Truth Table'!$V$3:$V$4098)=1,ABS(P13)<='Line Follower'!$C$6),FALSE) -> FALSE | Y14: =OR(Q14:X14) -> TRUE
B15: 12 | C15: 0 | D15: 0 | E15: 0 | F15: 0 | G15: 0 | H15: 1 | I15: 1 | J15: 0 | K15: 0 | L15: 0 | M15: 0 | N15: 0 | O15: 1 | P15: =IFERROR(_xlfn.XLOOKUP(_xlfn.TEXTJOIN(,,D14:O14),Aux!$B$3:$B$4098,'Truth Table'!$N$3:$N$4098),P14) -> -1 | Q15: {=IFERROR(_xlfn.XLOOKUP(_xlfn.TEXTJOIN(,,D15:O15),Aux!$B$3:$B$4098,'Truth Table'!$O$3:$S$4098)=1,FALSE)} -> TRUE | R15: FALSE | S15: FALSE | T15: FALSE | U15: FALSE | V15: =AND(_xlfn.XLOOKUP(_xlfn.TEXTJOIN(,,D15:O15),Aux!$B$3:$B$4098,'Truth Table'!$T$3:$T$4098)=1,P14<='Line Follower'!$C$7) -> FALSE | W15: =AND(_xlfn.XLOOKUP(_xlfn.TEXTJOIN(,,D15:O15),Aux!$B$3:$B$4098,'Truth Table'!$U$3:$U$4098)=1,P14>='Line Follower'!$C$6) -> FALSE | X15: =IFERROR(AND(_xlfn.XLOOKUP(_xlfn.TEXTJOIN(,,D15:O15),Aux!$B$3:$B$4098,'Truth Table'!$V$3:$V$4098)=1,ABS(P14)<='Line Follower'!$C$6),FALSE) -> FALSE | Y15: =OR(Q15:X15) -> TRUE
... B866: 863 | C866: 7592 | D866: 0 | E866: 1 | F866: 0 | G866: 0 | H866: 0 | I866: 0 | J866: 0 | K866: 0 | L866: 0 | M866: 0 | N866: 1 | O866: 0 | P866: =IFERROR(_xlfn.XLOOKUP(_xlfn.TEXTJOIN(,,D865:O865),Aux!$B$3:$B$4098,'Truth Table'!$N$3:$N$4098),P865) -> 7 | Q866: {=IFERROR(_xlfn.XLOOKUP(_xlfn.TEXTJOIN(,,D866:O866),Aux!$B$3:$B$4098,'Truth Table'!$O$3:$S$4098)=1,FALSE)} -> TRUE | R866: FALSE | S866: FALSE | T866: FALSE | U866: TRUE | V866: =AND(_xlfn.XLOOKUP(_xlfn.TEXTJOIN(,,D866:O866),Aux!$B$3:$B$4098,'Truth Table'!$T$3:$T$4098)=1,P865<='Line Follower'!$C$7) -> FALSE | W866: =AND(_xlfn.XLOOKUP(_xlfn.TEXTJOIN(,,D866:O866),Aux!$B$3:$B$4098,'Truth Table'!$U$3:$U$4098)=1,P865>='Line Follower'!$C$6) -> FALSE | X866: =IFERROR(AND(_xlfn.XLOOKUP(_xlfn.TEXTJOIN(,,D866:O866),Aux!$B$3:$B$4098,'Truth Table'!$V$3:$V$4098)=1,ABS(P865)<='Line Follower'!$C$6),FALSE) -> FALSE | Y866: =OR(Q866:X866) -> TRUE

Sheet Aux
B2: Text Representations | D2: Invalid Central Sensor Gaps
B3: =_xlfn.TEXTJOIN(,,'Truth Table'!B3:M3) -> 000000000000 | D3: =_xlfn.TEXTJOIN(,,E3:M3) -> 100000001 | E3: 1 | F3: 0 | G3: 0 | H3: 0 | I3: 0 | J3: 0 | K3: 0 | L3: 0 | M3: 1
B4: =_xlfn.TEXTJOIN(,,'Truth Table'!B4:M4) -> 100000000000 | D4: =_xlfn.TEXTJOIN(,,E4:M4) -> 10000001 | E4: 1 | F4: 0 | G4: 0 | H4: 0 | I4: 0 | J4: 0 | K4: 0 | L4: 1
B5: =_xlfn.TEXTJOIN(,,'Truth Table'!B5:M5) -> 010000000000 | D5: =_xlfn.TEXTJOIN(,,E5:M5) -> 1000001 | E5: 1 | F5: 0 | G5: 0 | H5: 0 | I5: 0 | J5: 0 | K5: 1
B6: =_xlfn.TEXTJOIN(,,'Truth Table'!B6:M6) -> 110000000000 | D6: =_xlfn.TEXTJOIN(,,E6:M6) -> 100001 | E6: 1 | F6: 0 | G6: 0 | H6: 0 | I6: 0 | J6: 1
B7: =_xlfn.TEXTJOIN(,,'Truth Table'!B7:M7) -> 001000000000 | D7: =_xlfn.TEXTJOIN(,,E7:M7) -> 10001 | E7: 1 | F7: 0 | G7: 0 | H7: 0 | I7: 1
B8: =_xlfn.TEXTJOIN(,,'Truth Table'!B8:M8) -> 101000000000 | D8: =_xlfn.TEXTJOIN(,,E8:M8) -> 1001 | E8: 1 | F8: 0 | G8: 0 | H8: 1
B9: =_xlfn.TEXTJOIN(,,'Truth Table'!B9:M9) -> 011000000000 | D9: =_xlfn.TEXTJOIN(,,E9:M9) -> 101 | E9: 1 | F9: 0 | G9: 1
B10: =_xlfn.TEXTJOIN(,,'Truth Table'!B10:M10) -> 111000000000
B11: =_xlfn.TEXTJOIN(,,'Truth Table'!B11:M11) -> 000100000000
B12: =_xlfn.TEXTJOIN(,,'Truth Table'!B12:M12) -> 100100000000
B13: =_xlfn.TEXTJOIN(,,'Truth Table'!B13:M13) -> 010100000000
B14: =_xlfn.TEXTJOIN(,,'Truth Table'!B14:M14) -> 110100000000
B15: =_xlfn.TEXTJOIN(,,'Truth Table'!B15:M15) -> 001100000000
B16: =_xlfn.TEXTJOIN(,,'Truth Table'!B16:M16) -> 101100000000
B17: =_xlfn.TEXTJOIN(,,'Truth Table'!B17:M17) -> 011100000000
B18: =_xlfn.TEXTJOIN(,,'Truth Table'!B18:M18) -> 111100000000
B19: =_xlfn.TEXTJOIN(,,'Truth Table'!B19:M19) -> 000010000000
B20: =_xlfn.TEXTJOIN(,,'Truth Table'!B20:M20) -> 100010000000
B21: =_xlfn.TEXTJOIN(,,'Truth Table'!B21:M21) -> 010010000000
... B4098: =_xlfn.TEXTJOIN(,,'Truth Table'!B4098:M4098) -> 111111111111
